Workbook

Sheet Leia-me
A1: Revisão jurídica do jogo Cidade Legal (Educa Direito)
A2: Conteúdo extraído do jogo em 29/10/2026: 803 afirmações (aulas, perguntas, casos, audiências, ocorrências, bairros, projetos de lei e eventos).
A4: Como revisar
A5: 1. Na aba "Revisão", leia o texto e a base legal citada.
A6: 2. Preencha apenas as colunas com fundo amarelo: Status, Correção sugerida, Revisado por e Data.
A7: 3. Status: "Correto", "Corrigir" (há erro), "Desatualizado" (a lei mudou) ou "Simplificar/esclarecer". Deixe "A revisar" enquanto não olhar.
A8: 4. Comece pelas linhas com Prioridade "Alta" (definem a resposta certa do jogo) e pelas marcadas na coluna "Atenção".
A9: 5. A aba "Resumo" atualiza sozinha o andamento da revisão.
A11: Exemplo de preenchimento
A12: Status: Corrigir · Correção sugerida: "O prazo é de 30 dias, não 15 (CDC, art. 18, §1º)" · Revisado por: Dra. Ana Lima · Data: 05/11/2026
A14: Depois da revisão, envie a planilha de volta ao Claude para aplicar as correções no jogo.
A15: Conteúdo educativo e simplificado: não substitui orientação jurídica profissional.

Sheet Revisão
A1: ID | B1: Onde no jogo | C1: Área do Direito | D1: Tipo | E1: Texto / afirmação | F1: Base legal citada | G1: Prioridade | H1: Atenção | I1: Status | J1: Correção sugerida | K1: Revisado por | L1: Data
A2: R001 | B2: Prefeitura › Aula | C2: Direito Constitucional e Administrativo | D2: Resumo da aula | E2: O município é um ente da federação com autonomia: tem prefeito, vereadores e leis próprias para assuntos de interesse local. | G2: Média | I2: A revisar
A3: R002 | B3: Prefeitura › Aula, ponto 1 | C3: Direito Constitucional e Administrativo | D3: Ponto da aula | E3: O Brasil é uma federação formada pela União, Estados, Distrito Federal e Municípios — todos autônomos (CF, art. 18). | F3: CF, art. 18 | G3: Média | I3: A revisar
A4: R003 | B4: Prefeitura › Aula, ponto 2 | C4: Direito Constitucional e Administrativo | D4: Ponto da aula | E4: O município legisla sobre assuntos de interesse local, como coleta de lixo, transporte urbano e uso do solo (CF, art. 30). | F4: CF, art. 30 | G4: Média | I4: A revisar
A5: R004 | B5: Prefeitura › Aula, ponto 3 | C5: Direito Constitucional e Administrativo | D5: Ponto da aula | E5: A administração pública segue o "LIMPE": Legalidade, Impessoalidade, Moralidade, Publicidade e Eficiência (CF, art. 37). | F5: CF, art. 37 | G5: Média | I5: A revisar
A6: R005 | B6: Prefeitura › Aula, ponto 4 | C6: Direito Constitucional e Administrativo | D6: Ponto da aula | E6: Para contratar obras e serviços, a prefeitura faz licitação (Lei 14.133/2021); para contratar servidores efetivos, concurso público (CF, art. 37, II). | F6: CF, art. 37, II | G6: Média | I6: A revisar
A7: R006 | B7: Prefeitura › Aula, na prática | C7: Direito Constitucional e Administrativo | D7: Exemplo prático | E7: O prefeito não pode contratar a empresa do primo sem licitação, nem nomear o filho para um cargo efetivo sem concurso. | G7: Média | I7: A revisar
A8: R007 | B8: Casas › Aula | C8: Direito Civil — Propriedade | D8: Resumo da aula | E8: A propriedade dá ao dono o direito de usar, aproveitar, vender e reaver o bem — mas ela deve cumprir sua função social. | G8: Média | I8: A revisar
A9: R008 | B9: Casas › Aula, ponto 1 | C9: Direito Civil — Propriedade | D9: Ponto da aula | E9: O proprietário pode usar, gozar, dispor e reaver a coisa de quem a possua injustamente (Código Civil, art. 1.228). | F9: Código Civil, art. 1.228 | G9: Média | I9: A revisar
A10: R009 | B10: Casas › Aula, ponto 2 | C10: Direito Civil — Propriedade | D10: Ponto da aula | E10: Imóvel só passa a ser seu com o registro da escritura no Cartório de Registro de Imóveis (CC, art. 1.245). "Contrato de gaveta" não transfere a propriedade. | G10: Média | I10: A revisar
A11: R010 | B11: Casas › Aula, ponto 3 | C11: Direito Civil — Propriedade | D11: Ponto da aula | E11: Usucapião: quem mora num imóvel urbano de até 250 m², por 5 anos, sem oposição e sem ter outro imóvel, pode se tornar dono (CF, art. 183). | F11: CF, art. 183 | G11: Média | I11: A revisar
A12: R011 | B12: Casas › Aula, ponto 4 | C12: Direito Civil — Propriedade | D12: Ponto da aula | E12: Imóveis públicos não podem ser adquiridos por usucapião (CF, art. 183, §3º). | F12: CF, art. 183, §3º | G12: Média | I12: A revisar
A13: R012 | B13: Casas › Aula, ponto 5 | C13: Direito Civil — Propriedade | D13: Ponto da aula | E13: O vizinho não pode fazer uso anormal da propriedade que prejudique o sossego, a saúde ou a segurança dos outros (CC, art. 1.277). | F13: CC, art. 1.277 | G13: Média | I13: A revisar
A14: R013 | B14: Casas › Aula, na prática | C14: Direito Civil — Propriedade | D14: Exemplo prático | E14: Comprou uma casa? Faça a escritura e registre no Cartório de Imóveis. Sem registro, o vendedor ainda é o dono no papel. | G14: Média | I14: A revisar
A15: R014 | B15: Casas › Prova, pergunta 1 | C15: Direito Civil — Propriedade | D15: Pergunta da prova | E15: Quando a propriedade de um imóvel é transferida ao comprador? → Resposta: Com o registro do título no Cartório de Registro de Imóveis. Pelo art. 1.245 do Código Civil, entre vivos a propriedade imobiliária só se transfere com o registro do título no Registro de Imóveis. | F15: Pelo art. 1.245 do Código Civil, entre vivos a propriedade imobiliária só se transfere com o registro do título no Registro de Imóveis. | G15: Alta | I15: A revisar
A16: R015 | B16: Casas › Prova, pergunta 2 | C16: Direito Civil — Propriedade | D16: Pergunta da prova | E16: Qual o prazo da usucapião especial urbana (imóvel de até 250 m² usado como moradia)? → Resposta: 5 anos. A CF, art. 183, prevê 5 anos de posse ininterrupta e sem oposição, desde que a pessoa não seja dona de outro imóvel. | F16: A CF, art. 183, prevê 5 anos de posse ininterrupta e sem oposição, desde que a pessoa não seja dona de outro imóvel. | G16: Alta | I16: A revisar
A17: R016 | B17: Casas › Prova, pergunta 3 | C17: Direito Civil — Propriedade | D17: Pergunta da prova | E17: É possível adquirir uma praça pública por usucapião? → Resposta: Não, bens públicos não são usucapíveis. A Constituição (art. 183, §3º e art. 191, parágrafo único) proíbe a usucapião de imóveis públicos. | F17: A Constituição (art. 183, §3º e art. 191, parágrafo único) proíbe a usucapião de imóveis públicos. | G17: Alta | I17: A revisar
A18: R017 | B18: Casas › Prova, pergunta 4 | C18: Direito Civil — Propriedade | D18: Pergunta da prova | E18: O vizinho faz festas barulhentas toda madrugada. Qual regra protege você? → Resposta: Direito de vizinhança — uso anormal da propriedade. O art. 1.277 do Código Civil permite ao vizinho fazer cessar interferências prejudiciais ao sossego, à saúde e à segurança. | F18: O art. 1.277 do Código Civil permite ao vizinho fazer cessar interferências prejudiciais ao sossego, à saúde e à segurança. | G18: Alta | I18: A revisar
A19: R018 | B19: Prédio de Aluguel › Aula | C19: Lei do Inquilinato | D19: Resumo da aula | E19: A Lei do Inquilinato (Lei 8.245/1991) regula a relação entre quem aluga (locador) e quem mora (locatário). | G19: Média | I19: A revisar
A20: R019 | B20: Prédio de Aluguel › Aula, ponto 1 | C20: Lei do Inquilinato | D20: Ponto da aula | E20: O locatário pode devolver o imóvel antes do fim do contrato pagando multa proporcional ao tempo que falta (art. 4º). | F20: art. 4º | G20: Média | I20: A revisar
A21: R020 | B21: Prédio de Aluguel › Aula, ponto 2 | C21: Lei do Inquilinato | D21: Ponto da aula | E21: O contrato pode exigir apenas UMA garantia: caução, fiança, seguro-fiança ou cessão fiduciária de quotas (art. 37). Exigir duas é contravenção. | G21: Média | I21: A revisar
A22: R021 | B22: Prédio de Aluguel › Aula, ponto 3 | C22: Lei do Inquilinato | D22: Ponto da aula | E22: A caução em dinheiro não pode passar de 3 meses de aluguel (art. 38, §2º). | F22: art. 38, §2º | G22: Média | I22: A revisar
A23: R022 | B23: Prédio de Aluguel › Aula, ponto 4 | C23: Lei do Inquilinato | D23: Ponto da aula | E23: Se o imóvel for vendido, o inquilino tem direito de preferência para comprá-lo nas mesmas condições (art. 27). | F23: art. 27 | G23: Média | I23: A revisar
A24: R023 | B24: Prédio de Aluguel › Aula, ponto 5 | C24: Lei do Inquilinato | D24: Ponto da aula | E24: O locador deve entregar o imóvel em condições de uso e pagar as despesas extraordinárias de condomínio, como reformas estruturais (art. 22). | F24: art. 22 | G24: Média | I24: A revisar
A25: R024 | B25: Prédio de Aluguel › Aula, na prática | C25: Lei do Inquilinato | D25: Exemplo prático | E25: Pediram fiador E seguro-fiança ao mesmo tempo? Isso é ilegal: a lei só permite uma modalidade de garantia por contrato. | G25: Média | I25: A revisar
A26: R025 | B26: Prédio de Aluguel › Prova, pergunta 1 | C26: Lei do Inquilinato | D26: Pergunta da prova | E26: Quantas modalidades de garantia o locador pode exigir no mesmo contrato? → Resposta: Uma. O parágrafo único do art. 37 da Lei 8.245/91 veda mais de uma modalidade de garantia no mesmo contrato. | F26: O parágrafo único do art. 37 da Lei 8.245/91 veda mais de uma modalidade de garantia no mesmo contrato. | G26: Alta | I26: A revisar
A27: R026 | B27: Prédio de Aluguel › Prova, pergunta 2 | C27: Lei do Inquilinato | D27: Pergunta da prova | E27: Qual o limite da caução em dinheiro? → Resposta: 3 meses de aluguel. O art. 38, §2º, limita a caução em dinheiro a 3 meses de aluguel, depositada em poupança. | F27: O art. 38, §2º, limita a caução em dinheiro a 3 meses de aluguel, depositada em poupança. | G27: Alta | I27: A revisar
A28: R027 | B28: Prédio de Aluguel › Prova, pergunta 3 | C28: Lei do Inquilinato | D28: Pergunta da prova | E28: O dono decide vender o apartamento alugado. O que o inquilino tem? → Resposta: Direito de preferência na compra. O art. 27 da Lei do Inquilinato garante ao locatário a preferência para adquirir o imóvel em igualdade de condições com terceiros. | F28: O art. 27 da Lei do Inquilinato garante ao locatário a preferência para adquirir o imóvel em igualdade de condições com terceiros. | G28: Alta | I28: A revisar
A29: R028 | B29: Mercado › Aula | C29: Direito do Consumidor | D29: Resumo da aula | E29: O Código de Defesa do Consumidor (Lei 8.078/1990) protege quem compra, porque o consumidor é a parte mais fraca da relação. | G29: Média | I29: A revisar
A30: R029 | B30: Mercado › Aula, ponto 1 | C30: Direito do Consumidor | D30: Ponto da aula | E30: Comprou fora da loja (internet, telefone, porta a porta)? Você tem 7 dias para desistir e receber tudo de volta (art. 49). | F30: art. 49 | G30: Média | I30: A revisar
A31: R030 | B31: Mercado › Aula, ponto 2 | C31: Direito do Consumidor | D31: Ponto da aula | E31: Prazo para reclamar de defeito aparente: 30 dias para produtos não duráveis (comida) e 90 dias para duráveis (eletrônicos) (art. 26). | F31: art. 26 | G31: Média | I31: A revisar
A32: R031 | B32: Mercado › Aula, ponto 3 | C32: Direito do Consumidor | D32: Ponto da aula | E32: Venda casada é proibida — a loja não pode obrigar você a levar um produto para comprar outro (art. 39, I). | F32: art. 39, I | G32: Média | I32: A revisar
A33: R032 | B33: Mercado › Aula, ponto 4 | C33: Direito do Consumidor | D33: Ponto da aula | E33: Propaganda enganosa ou abusiva é proibida, e a oferta anunciada obriga o fornecedor (arts. 30 e 37). | G33: Média | I33: A revisar
A34: R033 | B34: Mercado › Aula, ponto 5 | C34: Direito do Consumidor | D34: Ponto da aula | E34: O fornecedor responde pelos danos causados por defeito do produto mesmo sem culpa — é a responsabilidade objetiva (art. 12). | F34: art. 12 | G34: Média | I34: A revisar
A35: R034 | B35: Mercado › Aula, na prática | C35: Direito do Consumidor | D35: Exemplo prático | E35: O preço na etiqueta era menor que o do caixa? A oferta vincula a loja: você paga o menor preço anunciado. | G35: Média | I35: A revisar
A36: R035 | B36: Mercado › Prova, pergunta 1 | C36: Direito do Consumidor | D36: Pergunta da prova | E36: Comprei um tênis pela internet e me arrependi. Qual o prazo para desistir? → Resposta: 7 dias. O direito de arrependimento (art. 49 do CDC) vale por 7 dias para compras fora do estabelecimento comercial. | F36: O direito de arrependimento (art. 49 do CDC) vale por 7 dias para compras fora do estabelecimento comercial. | G36: Alta | I36: A revisar
A37: R036 | B37: Mercado › Prova, pergunta 2 | C37: Direito do Consumidor | D37: Pergunta da prova | E37: O cinema só deixa entrar quem comprar a pipoca dele. Isso é: → Resposta: Venda casada, prática abusiva. Condicionar o fornecimento de um produto ou serviço a outro é venda casada, proibida pelo art. 39, I, do CDC. | F37: Condicionar o fornecimento de um produto ou serviço a outro é venda casada, proibida pelo art. 39, I, do CDC. | G37: Alta | I37: A revisar
A38: R037 | B38: Mercado › Prova, pergunta 3 | C38: Direito do Consumidor | D38: Pergunta da prova | E38: Qual o prazo para reclamar de defeito aparente numa geladeira (produto durável)? → Resposta: 90 dias. Para produtos duráveis o prazo é de 90 dias (art. 26, II, do CDC); para não duráveis, 30 dias. | F38: Para produtos duráveis o prazo é de 90 dias (art. 26, II, do CDC); para não duráveis, 30 dias. | G38: Alta | I38: A revisar
A39: R038 | B39: Mercado › Prova, pergunta 4 | C39: Direito do Consumidor | D39: Pergunta da prova | E39: Um anúncio diz que o celular é à prova d'água, mas não é. Isso é: → Resposta: Propaganda enganosa. Informação falsa capaz de induzir o consumidor a erro é publicidade enganosa (art. 37, §1º, do CDC). | F39: Informação falsa capaz de induzir o consumidor a erro é publicidade enganosa (art. 37, §1º, do CDC). | G39: Alta | I39: A revisar
A40: R039 | B40: Fábrica › Aula | C40: Direito do Trabalho | D40: Resumo da aula | E40: A CLT e o art. 7º da Constituição garantem direitos mínimos a quem trabalha com carteira assinada. | G40: Média | I40: A revisar
...

Sheet Resumo
A1: Andamento da revisão
A3: Tipo | B3: A revisar | C3: Correto | D3: Corrigir | E3: Desatualizado | F3: Simplificar/esclarecer | G3: Total | H3: % revisado
A4: Ponto da aula | B4: =COUNTIFS(Revisão!$D$2:$D$804,$A4,Revisão!$I$2:$I$804,B$3) -> 286 | C4: =COUNTIFS(Revisão!$D$2:$D$804,$A4,Revisão!$I$2:$I$804,C$3) -> 0 | D4: =COUNTIFS(Revisão!$D$2:$D$804,$A4,Revisão!$I$2:$I$804,D$3) -> 0 | E4: =COUNTIFS(Revisão!$D$2:$D$804,$A4,Revisão!$I$2:$I$804,E$3) -> 0 | F4: =COUNTIFS(Revisão!$D$2:$D$804,$A4,Revisão!$I$2:$I$804,F$3) -> 0 | G4: =COUNTIF(Revisão!$D$2:$D$804,$A4) -> 286 | H4: =IF(G4=0,0,1-B4/G4) -> 0
A5: Pergunta da prova | B5: =COUNTIFS(Revisão!$D$2:$D$804,$A5,Revisão!$I$2:$I$804,B$3) -> 202 | C5: =COUNTIFS(Revisão!$D$2:$D$804,$A5,Revisão!$I$2:$I$804,C$3) -> 0 | D5: =COUNTIFS(Revisão!$D$2:$D$804,$A5,Revisão!$I$2:$I$804,D$3) -> 0 | E5: =COUNTIFS(Revisão!$D$2:$D$804,$A5,Revisão!$I$2:$I$804,E$3) -> 0 | F5: =COUNTIFS(Revisão!$D$2:$D$804,$A5,Revisão!$I$2:$I$804,F$3) -> 0 | G5: =COUNTIF(Revisão!$D$2:$D$804,$A5) -> 202 | H5: =IF(G5=0,0,1-B5/G5) -> 0
A6: Caso de cidadão | B6: =COUNTIFS(Revisão!$D$2:$D$804,$A6,Revisão!$I$2:$I$804,B$3) -> 129 | C6: =COUNTIFS(Revisão!$D$2:$D$804,$A6,Revisão!$I$2:$I$804,C$3) -> 0 | D6: =COUNTIFS(Revisão!$D$2:$D$804,$A6,Revisão!$I$2:$I$804,D$3) -> 0 | E6: =COUNTIFS(Revisão!$D$2:$D$804,$A6,Revisão!$I$2:$I$804,E$3) -> 0 | F6: =COUNTIFS(Revisão!$D$2:$D$804,$A6,Revisão!$I$2:$I$804,F$3) -> 0 | G6: =COUNTIF(Revisão!$D$2:$D$804,$A6) -> 129 | H6: =IF(G6=0,0,1-B6/G6) -> 0
A7: Exemplo prático | B7: =COUNTIFS(Revisão!$D$2:$D$804,$A7,Revisão!$I$2:$I$804,B$3) -> 67 | C7: =COUNTIFS(Revisão!$D$2:$D$804,$A7,Revisão!$I$2:$I$804,C$3) -> 0 | D7: =COUNTIFS(Revisão!$D$2:$D$804,$A7,Revisão!$I$2:$I$804,D$3) -> 0 | E7: =COUNTIFS(Revisão!$D$2:$D$804,$A7,Revisão!$I$2:$I$804,E$3) -> 0 | F7: =COUNTIFS(Revisão!$D$2:$D$804,$A7,Revisão!$I$2:$I$804,F$3) -> 0 | G7: =COUNTIF(Revisão!$D$2:$D$804,$A7) -> 67 | H7: =IF(G7=0,0,1-B7/G7) -> 0
A8: Resumo da aula | B8: =COUNTIFS(Revisão!$D$2:$D$804,$A8,Revisão!$I$2:$I$804,B$3) -> 67 | C8: =COUNTIFS(Revisão!$D$2:$D$804,$A8,Revisão!$I$2:$I$804,C$3) -> 0 | D8: =COUNTIFS(Revisão!$D$2:$D$804,$A8,Revisão!$I$2:$I$804,D$3) -> 0 | E8: =COUNTIFS(Revisão!$D$2:$D$804,$A8,Revisão!$I$2:$I$804,E$3) -> 0 | F8: =COUNTIFS(Revisão!$D$2:$D$804,$A8,Revisão!$I$2:$I$804,F$3) -> 0 | G8: =COUNTIF(Revisão!$D$2:$D$804,$A8) -> 67 | H8: =IF(G8=0,0,1-B8/G8) -> 0
A9: Lei do bairro | B9: =COUNTIFS(Revisão!$D$2:$D$804,$A9,Revisão!$I$2:$I$804,B$3) -> 24 | C9: =COUNTIFS(Revisão!$D$2:$D$804,$A9,Revisão!$I$2:$I$804,C$3) -> 0 | D9: =COUNTIFS(Revisão!$D$2:$D$804,$A9,Revisão!$I$2:$I$804,D$3) -> 0 | E9: =COUNTIFS(Revisão!$D$2:$D$804,$A9,Revisão!$I$2:$I$804,E$3) -> 0 | F9: =COUNTIFS(Revisão!$D$2:$D$804,$A9,Revisão!$I$2:$I$804,F$3) -> 0 | G9: =COUNTIF(Revisão!$D$2:$D$804,$A9) -> 24 | H9: =IF(G9=0,0,1-B9/G9) -> 0
A10: Projeto de lei | B10: =COUNTIFS(Revisão!$D$2:$D$804,$A10,Revisão!$I$2:$I$804,B$3) -> 9 | C10: =COUNTIFS(Revisão!$D$2:$D$804,$A10,Revisão!$I$2:$I$804,C$3) -> 0 | D10: =COUNTIFS(Revisão!$D$2:$D$804,$A10,Revisão!$I$2:$I$804,D$3) -> 0 | E10: =COUNTIFS(Revisão!$D$2:$D$804,$A10,Revisão!$I$2:$I$804,E$3) -> 0 | F10: =COUNTIFS(Revisão!$D$2:$D$804,$A10,Revisão!$I$2:$I$804,F$3) -> 0 | G10: =COUNTIF(Revisão!$D$2:$D$804,$A10) -> 9 | H10: =IF(G10=0,0,1-B10/G10) -> 0
A11: Ocorrência | B11: =COUNTIFS(Revisão!$D$2:$D$804,$A11,Revisão!$I$2:$I$804,B$3) -> 5 | C11: =COUNTIFS(Revisão!$D$2:$D$804,$A11,Revisão!$I$2:$I$804,C$3) -> 0 | D11: =COUNTIFS(Revisão!$D$2:$D$804,$A11,Revisão!$I$2:$I$804,D$3) -> 0 | E11: =COUNTIFS(Revisão!$D$2:$D$804,$A11,Revisão!$I$2:$I$804,E$3) -> 0 | F11: =COUNTIFS(Revisão!$D$2:$D$804,$A11,Revisão!$I$2:$I$804,F$3) -> 0 | G11: =COUNTIF(Revisão!$D$2:$D$804,$A11) -> 5 | H11: =IF(G11=0,0,1-B11/G11) -> 0
A12: Dica de lei do evento | B12: =COUNTIFS(Revisão!$D$2:$D$804,$A12,Revisão!$I$2:$I$804,B$3) -> 5 | C12: =COUNTIFS(Revisão!$D$2:$D$804,$A12,Revisão!$I$2:$I$804,C$3) -> 0 | D12: =COUNTIFS(Revisão!$D$2:$D$804,$A12,Revisão!$I$2:$I$804,D$3) -> 0 | E12: =COUNTIFS(Revisão!$D$2:$D$804,$A12,Revisão!$I$2:$I$804,E$3) -> 0 | F12: =COUNTIFS(Revisão!$D$2:$D$804,$A12,Revisão!$I$2:$I$804,F$3) -> 0 | G12: =COUNTIF(Revisão!$D$2:$D$804,$A12) -> 5 | H12: =IF(G12=0,0,1-B12/G12) -> 0
A13: Audiência no Fórum | B13: =COUNTIFS(Revisão!$D$2:$D$804,$A13,Revisão!$I$2:$I$804,B$3) -> 5 | C13: =COUNTIFS(Revisão!$D$2:$D$804,$A13,Revisão!$I$2:$I$804,C$3) -> 0 | D13: =COUNTIFS(Revisão!$D$2:$D$804,$A13,Revisão!$I$2:$I$804,D$3) -> 0 | E13: =COUNTIFS(Revisão!$D$2:$D$804,$A13,Revisão!$I$2:$I$804,E$3) -> 0 | F13: =COUNTIFS(Revisão!$D$2:$D$804,$A13,Revisão!$I$2:$I$804,F$3) -> 0 | G13: =COUNTIF(Revisão!$D$2:$D$804,$A13) -> 5 | H13: =IF(G13=0,0,1-B13/G13) -> 0
A14: Descrição | B14: =COUNTIFS(Revisão!$D$2:$D$804,$A14,Revisão!$I$2:$I$804,B$3) -> 4 | C14: =COUNTIFS(Revisão!$D$2:$D$804,$A14,Revisão!$I$2:$I$804,C$3) -> 0 | D14: =COUNTIFS(Revisão!$D$2:$D$804,$A14,Revisão!$I$2:$I$804,D$3) -> 0 | E14: =COUNTIFS(Revisão!$D$2:$D$804,$A14,Revisão!$I$2:$I$804,E$3) -> 0 | F14: =COUNTIFS(Revisão!$D$2:$D$804,$A14,Revisão!$I$2:$I$804,F$3) -> 0 | G14: =COUNTIF(Revisão!$D$2:$D$804,$A14) -> 4 | H14: =IF(G14=0,0,1-B14/G14) -> 0
A15: Total | B15: =SUM(B4:B14) -> 803 | C15: =SUM(C4:C14) -> 0 | D15: =SUM(D4:D14) -> 0 | E15: =SUM(E4:E14) -> 0 | F15: =SUM(F4:F14) -> 0 | G15: =SUM(G4:G14) -> 803 | H15: =IF(G15=0,0,1-B15/G15) -> 0
A17: Itens com prioridade Alta ainda a revisar | B17: =COUNTIFS(Revisão!$G$2:$G$804,"Alta",Revisão!$I$2:$I$804,"A revisar") -> 350
A18: Itens marcados em "Atenção" ainda a revisar | B18: =COUNTIFS(Revisão!$H$2:$H$804,"?*",Revisão!$I$2:$I$804,"A revisar") -> 42
